Workbook

Sheet Tabla 1
A1: Fecha | B1: Título de la Nota | C1: Medio | D1: Gestión | E1: Detalle de Gestión | F1: Síntesis | G1: Link | H1: Tipo de Medio | I1: Tier | J1: Valor de Retorno ($$) | K1: Tono (K) | L1: Mensaje Clave (L) | M1: Eje/Tema (M) | N1: Subtema (N) | O1: Voceros (O) | P1: % del Tema (P)
A2: 46024 | B2: El complejo recreativo Maldonado reabre sus puertas para la temporada 2026 | C2: La Nueva Provincia | D2: Espontánea | E2: Orgánica | F2: Anuncio de la reapertura del complejo recreativo Maldonado para la temporada de verano 2026. | G2: https://www.lanueva.com/nota/2025-12-30-17-13-0-el-complejo-recreativo-maldonado-reabre-sus-puertas-para-la-temporada-2026 | H2: =IF(C2="", "", IFERROR(VLOOKUP(C2, 'Tabla 2'!$A$2:$D$298, 2, FALSE), "")) -> Local BB | I2: =IF(C2="", "", IFERROR(VLOOKUP(C2, 'Tabla 2'!$A$2:$D$298, 3, FALSE), "")) -> 1 | J2: =IF(C2="", "", IFERROR(VLOOKUP(C2, 'Tabla 2'!$A$2:$D$298, 4, FALSE), "")) -> 900000 | K2: Positivo | L2: TRUE | M2: Sustentabilidad | N2: Relaciones con la Comunidad | O2: No menciona | P2: 1
A3: 46024 | B3: El complejo recreativo Maldonado reabre sus puertas para la temporada 2026 | C3: Ingeniero White | D3: Espontánea | E3: Orgánica | F3: Noticia sobre la reapertura del complejo recreativo Maldonado para la temporada 2026. | G3: https://www.ingenierowhite.com/2025/12/30/el-complejo-recreativo-maldonado-reabre-sus-puertas-para-la-temporada-2026/ | H3: =IF(C3="", "", IFERROR(VLOOKUP(C3, 'Tabla 2'!$A$2:$D$298, 2, FALSE), "")) -> Local BB | I3: =IF(C3="", "", IFERROR(VLOOKUP(C3, 'Tabla 2'!$A$2:$D$298, 3, FALSE), "")) -> 1 | J3: =IF(C3="", "", IFERROR(VLOOKUP(C3, 'Tabla 2'!$A$2:$D$298, 4, FALSE), "")) -> 500000 | K3: Positivo | L3: TRUE | M3: Sustentabilidad | N3: Relaciones con la Comunidad | O3: No menciona | P3: 1
A4: 46024 | B4: El viernes abrirá sus puertas el balneario Maldonado | C4: Frente a Cano | D4: Espontánea | E4: Orgánica | F4: Anuncio de la apertura del balneario Maldonado el próximo viernes. | G4: https://frenteacano.com.ar/el-viernes-abrira-sus-puertas-el-balneario-maldonado/ | H4: =IF(C4="", "", IFERROR(VLOOKUP(C4, 'Tabla 2'!$A$2:$D$298, 2, FALSE), "")) -> Local BB | I4: =IF(C4="", "", IFERROR(VLOOKUP(C4, 'Tabla 2'!$A$2:$D$298, 3, FALSE), "")) -> 1 | J4: =IF(C4="", "", IFERROR(VLOOKUP(C4, 'Tabla 2'!$A$2:$D$298, 4, FALSE), "")) -> 800000 | K4: Positivo | L4: TRUE | M4: Sustentabilidad | N4: Relaciones con la Comunidad | O4: No menciona | P4: 1
A5: 46024 | B5: Complejo Maldonado abre sus puertas el viernes | C5: Canal 7 Bahia Blanca | D5: Espontánea | E5: Orgánica | F5: Detalles sobre la apertura del Complejo Maldonado, incluyendo horarios y normas de ingreso. | G5: https://www.canalsiete.com.ar/c7-noticias/c7-destacada/2025/12/30/complejo-maldonado-abre-sus-puertas-el-viernes/#:~:text=El%20Maldonado%20abrir%C3%A1%20todos%20los%20d%C3%ADas%20de%209%20a%2021%20hs.&text=En%20su%20ingreso%20se%20debe,el%20ingreso%20de%20bebidas%20alcoh%C3%B3licas. | H5: =IF(C5="", "", IFERROR(VLOOKUP(C5, 'Tabla 2'!$A$2:$D$298, 2, FALSE), "")) -> Local BB | I5: =IF(C5="", "", IFERROR(VLOOKUP(C5, 'Tabla 2'!$A$2:$D$298, 3, FALSE), "")) -> 1 | J5: =IF(C5="", "", IFERROR(VLOOKUP(C5, 'Tabla 2'!$A$2:$D$298, 4, FALSE), "")) -> 5000000 | K5: Positivo | L5: TRUE | M5: Sustentabilidad | N5: Relaciones con la Comunidad | O5: No menciona | P5: 1
A6: 46024 | B6: El balneario Maldonado ya tiene todo preparado para la inauguración de temporada 2026 | C6: 0291 Noticias | D6: Espontánea | E6: Orgánica | F6: Preparativos finales para la inauguración de la temporada 2026 en el balneario Maldonado. | G6: https://0291.com.ar/el-balneario-maldonado-ya-tiene-todo-preparado-para-la-inauguracion-de-temporada-2026/ | H6: =IF(C6="", "", IFERROR(VLOOKUP(C6, 'Tabla 2'!$A$2:$D$298, 2, FALSE), "")) -> Local BB | I6: =IF(C6="", "", IFERROR(VLOOKUP(C6, 'Tabla 2'!$A$2:$D$298, 3, FALSE), "")) -> 3 | J6: =IF(C6="", "", IFERROR(VLOOKUP(C6, 'Tabla 2'!$A$2:$D$298, 4, FALSE), "")) -> 0 | K6: Positivo | L6: TRUE | M6: Sustentabilidad | N6: Relaciones con la Comunidad | O6: No menciona | P6: 1
A7: 46024 | B7: El balneario Maldonado habilitó la temporada 2026 | C7: Café x Medio | D7: Espontánea | E7: Orgánica | F7: Confirmación de la habilitación de la temporada 2026 en el balneario Maldonado. | G7: https://cafexmedio.com.ar/locales/el-balneario-maldonado-habilito-la-temporada-2026/ | H7: =IF(C7="", "", IFERROR(VLOOKUP(C7, 'Tabla 2'!$A$2:$D$298, 2, FALSE), "")) -> Local BB | I7: =IF(C7="", "", IFERROR(VLOOKUP(C7, 'Tabla 2'!$A$2:$D$298, 3, FALSE), "")) -> 2 | J7: =IF(C7="", "", IFERROR(VLOOKUP(C7, 'Tabla 2'!$A$2:$D$298, 4, FALSE), "")) -> 0 | K7: Positivo | L7: TRUE | M7: Sustentabilidad | N7: Relaciones con la Comunidad | O7: No menciona | P7: 1
A8: 46024 | B8: El complejo recreativo Maldonado reabre sus puertas para la temporada 2026 | C8: ArgenSUR | D8: Espontánea | E8: Orgánica | F8: Anuncio de la reapertura del complejo recreativo Maldonado para la temporada de verano 2026. | G8: https://argensur.com.ar/publicacion/22822/el-complejo-recreativo-maldonado-reabre-sus-puertas-para-la-temporada-2026/ | H8: =IF(C8="", "", IFERROR(VLOOKUP(C8, 'Tabla 2'!$A$2:$D$298, 2, FALSE), "")) -> Generalista Nacional | I8: =IF(C8="", "", IFERROR(VLOOKUP(C8, 'Tabla 2'!$A$2:$D$298, 3, FALSE), "")) -> 3 | J8: =IF(C8="", "", IFERROR(VLOOKUP(C8, 'Tabla 2'!$A$2:$D$298, 4, FALSE), "")) -> 0 | K8: Positivo | L8: TRUE | M8: Sustentabilidad | N8: Relaciones con la Comunidad | O8: No menciona | P8: 1
A9: 46024 | B9: Bahía Blanca: el balneario Maldonado habilitó la temporada 2026 | C9: Mega 97.5 | D9: Espontánea | E9: Orgánica | F9: Confirmación de la habilitación de la temporada 2026 en el balneario Maldonado. | G9: https://mega975.com.ar/bahia-blanca-el-balneario-maldonado-habilito-la-temporada-2026/ | H9: =IF(C9="", "", IFERROR(VLOOKUP(C9, 'Tabla 2'!$A$2:$D$298, 2, FALSE), "")) -> Generalista Nacional | I9: =IF(C9="", "", IFERROR(VLOOKUP(C9, 'Tabla 2'!$A$2:$D$298, 3, FALSE), "")) -> 3 | J9: =IF(C9="", "", IFERROR(VLOOKUP(C9, 'Tabla 2'!$A$2:$D$298, 4, FALSE), "")) -> 0 | K9: Positivo | L9: TRUE | M9: Sustentabilidad | N9: Relaciones con la Comunidad | O9: No menciona | P9: 1
A10: 46024 | B10: Centro Industrial y Logístico | C10: Bahía Productiva | D10: Espontánea | E10: =IF(OR(D10="Espontánea", D10="Reactiva"), "Orgánica", "") -> Orgánica | F10: Información de interés sobre la industria local. | G10: https://bahiaproductiva.com/info-de-interes/industria/ | H10: =IF(C10="", "", IFERROR(VLOOKUP(C10, 'Tabla 2'!$A$2:$D$298, 2, FALSE), "")) -> Local BB | I10: =IF(C10="", "", IFERROR(VLOOKUP(C10, 'Tabla 2'!$A$2:$D$298, 3, FALSE), "")) -> 3 | J10: =IF(C10="", "", IFERROR(VLOOKUP(C10, 'Tabla 2'!$A$2:$D$298, 4, FALSE), "")) -> 0 | K10: Positivo | L10: TRUE | M10: Proveedor Estratégico | N10: Cadena de Valor y Sectores | O10: No menciona | P10: 1
A11: 46024 | B11: Bahía Blanca | C11: Bahía Productiva | D11: Espontánea | E11: =IF(OR(D11="Espontánea", D11="Reactiva"), "Orgánica", "") -> Orgánica | F11: Información de interés general sobre la ciudad de Bahía Blanca. | G11: https://bahiaproductiva.com/info-de-interes/bahia-blanca/ | H11: =IF(C11="", "", IFERROR(VLOOKUP(C11, 'Tabla 2'!$A$2:$D$298, 2, FALSE), "")) -> Local BB | I11: =IF(C11="", "", IFERROR(VLOOKUP(C11, 'Tabla 2'!$A$2:$D$298, 3, FALSE), "")) -> 3 | J11: =IF(C11="", "", IFERROR(VLOOKUP(C11, 'Tabla 2'!$A$2:$D$298, 4, FALSE), "")) -> 0 | K11: Positivo | L11: TRUE | M11: Sustentabilidad | N11: Relaciones con la Comunidad | O11: No menciona | P11: 1
A12: 46027 | B12: Sanar después de la tormenta: reconstruir una comunidad cuando el daño no se ve | C12: Visión Sustentable | D12: Proactiva | E12: Orgánica | F12: Reflexión sobre la reconstrucción comunitaria y el impacto invisible tras una tormenta. | G12: https://www.visionsustentable.com/2026/01/05/sanar-despues-de-la-tormenta-reconstruir-una-comunidad-cuando-el-dano-no-se-ve/ | H12: =IF(C12="", "", IFERROR(VLOOKUP(C12, 'Tabla 2'!$A$2:$D$298, 2, FALSE), "")) -> Sustentabilidad Nacional | I12: =IF(C12="", "", IFERROR(VLOOKUP(C12, 'Tabla 2'!$A$2:$D$298, 3, FALSE), "")) -> 1 | J12: =IF(C12="", "", IFERROR(VLOOKUP(C12, 'Tabla 2'!$A$2:$D$298, 4, FALSE), "")) -> 600000 | K12: Positivo | L12: TRUE | M12: Sustentabilidad | N12: Relaciones con la Comunidad | O12: No menciona | P12: 1
A13: 46028 | B13: Las acciones llevadas a cabo por la Dirección Institucional | C13: Tiempo Industrial | D13: Espontánea | E13: Orgánica | F13: La inundación del 7 de marzo afectó las instalaciones de la UIBB. Además, muchas pymes estuvieron complicadas, lo que motivó a repensar la planificación anual. | G13: https://sentinel.globalnewsgroup.com/ver-noticia?ysTe9aO_9pWtqaYiIJ0yHIzJCBqMZA1s0CXXdYARVPY | H13: =IF(C13="", "", IFERROR(VLOOKUP(C13, 'Tabla 2'!$A$2:$D$298, 2, FALSE), "")) -> Local BB | I13: =IF(C13="", "", IFERROR(VLOOKUP(C13, 'Tabla 2'!$A$2:$D$298, 3, FALSE), "")) -> 3 | J13: =IF(C13="", "", IFERROR(VLOOKUP(C13, 'Tabla 2'!$A$2:$D$298, 4, FALSE), "")) -> 0 | K13: Positivo | L13: FALSE | M13: Institucional | N13: Generalidades | O13: No menciona | P13: 1
A14: 46059 | B14: Cómo funciona la biblia de la industria química y petroquímica para dejar de contaminar | C14: Economía Sustentable | D14: Espontánea | E14: =IF(OR(D14="Espontánea", D14="Reactiva"), "Orgánica", "") -> Orgánica | F14: Artículo sobre el funcionamiento de la guía de la industria química y petroquímica para reducir la contaminación. | G14: https://economiasustentable.com/noticias/como-funciona-la-biblia-de-la-industria-quimica-y-petroquimica-para-dejar-de-contaminar/ | H14: =IF(C14="", "", IFERROR(VLOOKUP(C14, 'Tabla 2'!$A$2:$D$298, 2, FALSE), "")) -> Sustentabilidad Nacional | I14: =IF(C14="", "", IFERROR(VLOOKUP(C14, 'Tabla 2'!$A$2:$D$298, 3, FALSE), "")) -> 3 | J14: =IF(C14="", "", IFERROR(VLOOKUP(C14, 'Tabla 2'!$A$2:$D$298, 4, FALSE), "")) -> 0 | K14: Positivo | L14: TRUE | M14: Sustentabilidad | N14: Estrategia ESG | O14: No menciona | P14: 1
A15: 46059 | B15: Hoy la sostenibilidad pasa por sostener el empleo y la productividad y eso tiene que ver con competitividad | C15: Sustenomics | D15: Espontánea | E15: Orgánica | F15: Reflexión sobre cómo la sostenibilidad actual se relaciona con el mantenimiento del empleo, la productividad y la competitividad. | G15: https://sustenomics.com/hoy-la-sostenibilidad-pasa-por-sostener-el-empleo-y-la-productividad-y-eso-tiene-que-ver-con-competitividad/ | H15: =IF(C15="", "", IFERROR(VLOOKUP(C15, 'Tabla 2'!$A$2:$D$298, 2, FALSE), "")) -> Sustentabilidad Nacional | I15: =IF(C15="", "", IFERROR(VLOOKUP(C15, 'Tabla 2'!$A$2:$D$298, 3, FALSE), "")) -> 1 | J15: =IF(C15="", "", IFERROR(VLOOKUP(C15, 'Tabla 2'!$A$2:$D$298, 4, FALSE), "")) -> 700000 | K15: Positivo | L15: TRUE | M15: Sustentabilidad | N15: Estrategia ESG | O15: No menciona | P15: 1
A16: 46062 | B16: Guillermo Petracci, de Unipar: "El desarrollo de quienes forman Unipar es nuestra prioridad" | C16: Mercado | D16: Proactiva | E16: Orgánica | F16: Libro Blanco de RSE | G16: https://drive.google.com/file/d/1TOPVGerlf-EtMckPhQHK7da1fSrz-1M6/view?usp=sharing | H16: =IF(C16="", "", IFERROR(VLOOKUP(C16, 'Tabla 2'!$A$2:$D$298, 2, FALSE), "")) -> Negocio Nacional | I16: =IF(C16="", "", IFERROR(VLOOKUP(C16, 'Tabla 2'!$A$2:$D$298, 3, FALSE), "")) -> 1 | J16: =IF(C16="", "", IFERROR(VLOOKUP(C16, 'Tabla 2'!$A$2:$D$298, 4, FALSE), "")) -> 500000 | K16: Positivo | L16: TRUE | M16: Institucional | N16: Marca Empleadora/RRHH | O16: Guillermo Petracci | P16: 1
A17: 46064 | B17: Premio Conciencia: una mirada multisectorial para reconocer impacto real | C17: NBS | D17: Proactiva | E17: Orgánica | F17: Cobertura sobre el Premio Conciencia y su enfoque multisectorial para reconocer el impacto real. | G17: https://nbs.ar/premio-conciencia-una-mirada-multisectorial-para-reconocer-impacto-real/ | H17: =IF(C17="", "", IFERROR(VLOOKUP(C17, 'Tabla 2'!$A$2:$D$298, 2, FALSE), "")) -> Generalista Nacional | I17: =IF(C17="", "", IFERROR(VLOOKUP(C17, 'Tabla 2'!$A$2:$D$298, 3, FALSE), "")) -> 3 | J17: =IF(C17="", "", IFERROR(VLOOKUP(C17, 'Tabla 2'!$A$2:$D$298, 4, FALSE), "")) -> 0 | K17: Positivo | L17: TRUE | M17: Sustentabilidad | N17: Estrategia ESG | O17: No menciona | P17: 1
A18: 46064 | B18: Revista N° 351 | C18: NBS | D18: Proactiva | E18: Orgánica | F18: Publicación de la edición N° 351 de la revista. | G18: https://nbs.ar/project/revista-no-351/ | H18: =IF(C18="", "", IFERROR(VLOOKUP(C18, 'Tabla 2'!$A$2:$D$298, 2, FALSE), "")) -> Generalista Nacional | I18: =IF(C18="", "", IFERROR(VLOOKUP(C18, 'Tabla 2'!$A$2:$D$298, 3, FALSE), "")) -> 3 | J18: =IF(C18="", "", IFERROR(VLOOKUP(C18, 'Tabla 2'!$A$2:$D$298, 4, FALSE), "")) -> 0 | K18: Positivo | L18: FALSE | M18: Institucional | N18: Generalidades | O18: No menciona | P18: 1
A19: 46065 | B19: Inauguración de nuevos servicios de oncología y hematología en el Hospital Municipal | C19: 0291 Noticias | D19: Espontánea | E19: =IF(OR(D19="Espontánea", D19="Reactiva"), "Orgánica", "") -> Orgánica | F19: Noticia sobre la inauguración de las nuevas áreas de oncología y hematología en el Hospital Municipal. | G19: https://0291.com.ar/inauguracion-de-nuevos-servicios-de-oncologia-y-hematologia-en-el-hospital-municipal/ | H19: =IF(C19="", "", IFERROR(VLOOKUP(C19, 'Tabla 2'!$A$2:$D$298, 2, FALSE), "")) -> Local BB | I19: =IF(C19="", "", IFERROR(VLOOKUP(C19, 'Tabla 2'!$A$2:$D$298, 3, FALSE), "")) -> 3 | J19: =IF(C19="", "", IFERROR(VLOOKUP(C19, 'Tabla 2'!$A$2:$D$298, 4, FALSE), "")) -> 0 | K19: Positivo | M19: Sustentabilidad | N19: Relaciones con la Comunidad | O19: No menciona | P19: 1
A20: 46065 | B20: El Hospital Municipal inauguró los nuevos servicios de oncología y hematología | C20: Frente a Cano | D20: Espontánea | E20: =IF(OR(D20="Espontánea", D20="Reactiva"), "Orgánica", "") -> Orgánica | F20: Reporte de la apertura de los nuevos servicios de oncología y hematología en el Hospital Municipal. | G20: https://frenteacano.com.ar/el-hospital-municipal-inauguro-los-nuevos-servicios-de-oncologia-y-hematologia/ | H20: =IF(C20="", "", IFERROR(VLOOKUP(C20, 'Tabla 2'!$A$2:$D$298, 2, FALSE), "")) -> Local BB | I20: =IF(C20="", "", IFERROR(VLOOKUP(C20, 'Tabla 2'!$A$2:$D$298, 3, FALSE), "")) -> 1 | J20: =IF(C20="", "", IFERROR(VLOOKUP(C20, 'Tabla 2'!$A$2:$D$298, 4, FALSE), "")) -> 800000 | K20: Positivo | L20: FALSE | M20: Sustentabilidad | N20: Relaciones con la Comunidad | O20: No menciona | P20: 1
A21: 46065 | B21: El intendente inauguró los nuevos servicios de oncología y hematología en el Hospital Municipal junto a autoridades y trabajadores de la salud | C21: Ingeniero White | D21: Espontánea | E21: =IF(OR(D21="Espontánea", D21="Reactiva"), "Orgánica", "") -> Orgánica | F21: Cobertura de la inauguración de servicios de salud en el Hospital Municipal por parte del intendente. | G21: https://www.ingenierowhite.com/2026/02/12/el-intendente-inauguro-los-nuevos-servicios-de-oncologia-y-hematologia-en-el-hospital-municipal-junto-a-autoridades-y-trabajadores-de-la-salud/ | H21: =IF(C21="", "", IFERROR(VLOOKUP(C21, 'Tabla 2'!$A$2:$D$298, 2, FALSE), "")) -> Local BB | I21: =IF(C21="", "", IFERROR(VLOOKUP(C21, 'Tabla 2'!$A$2:$D$298, 3, FALSE), "")) -> 1 | J21: =IF(C21="", "", IFERROR(VLOOKUP(C21, 'Tabla 2'!$A$2:$D$298, 4, FALSE), "")) -> 500000 | K21: Positivo | M21: Sustentabilidad | N21: Relaciones con la Comunidad | O21: No menciona | P21: 1
A22: 46065 | B22: Quienes tenían compromisos reales con enfoque de gestión pudieron sostener las agendas de sostenibilidad | C22: Sustenomics | D22: Espontánea | E22: =IF(D22<>"","Orgánica","") -> Orgánica | F22: Artículo sobre cómo los compromisos reales con enfoque de gestión sostuvieron las agendas de sostenibilidad. | G22: https://sustenomics.com/quienes-tenian-compromisos-reales-con-enfoque-de-gestion-pudieron-sostener-las-agendas-de-sostenibilidad/ | H22: =IF(C22="", "", IFERROR(VLOOKUP(C22, 'Tabla 2'!$A$2:$D$298, 2, FALSE), "")) -> Sustentabilidad Nacional | I22: =IF(C22="", "", IFERROR(VLOOKUP(C22, 'Tabla 2'!$A$2:$D$298, 3, FALSE), "")) -> 1 | J22: =IF(C22="", "", IFERROR(VLOOKUP(C22, 'Tabla 2'!$A$2:$D$298, 4, FALSE), "")) -> 700000 | K22: Positivo | L22: TRUE | M22: Sustentabilidad | N22: Estrategia ESG | O22: No menciona | P22: 1
A23: 46068 | B23: Guillermo Petracci de Unipar: la variable ESG actúa como un motor de innovación | C23: Mercado | D23: Proactiva | E23: =IF(D23<>"","Orgánica","") -> Orgánica | F23: Entrevista a Guillermo Petracci sobre cómo la variable ESG actúa como motor de innovación en Unipar. | G23: https://mercado.com.ar/gestion-sustentable/guillermo-petracci-de-unipar-la-variable-esg-actua-como-un-motor-de-innovacion/#:~:text=Asimismo%2C%20el%20desarrollo%20de%20quienes,motor%20de%20nuestra%20excelencia%20operativa. | H23: =IF(C23="", "", IFERROR(VLOOKUP(C23, 'Tabla 2'!$A$2:$D$298, 2, FALSE), "")) -> Negocio Nacional | I23: =IF(C23="", "", IFERROR(VLOOKUP(C23, 'Tabla 2'!$A$2:$D$298, 3, FALSE), "")) -> 1 | J23: =IF(C23="", "", IFERROR(VLOOKUP(C23, 'Tabla 2'!$A$2:$D$298, 4, FALSE), "")) -> 500000 | K23: Positivo | L23: TRUE | M23: Sustentabilidad | N23: Estrategia ESG | O23: Guillermo Petracci | P23: 1
A24: 46075 | B24: El Hospital Municipal consolida su plan director con una ampliación histórica | C24: La Nueva Provincia | D24: Espontánea | E24: =IF(D24<>"","Orgánica","") -> Orgánica | F24: Cobertura sobre la consolidación del plan director y la ampliación histórica del Hospital Municipal. | G24: https://www.lanueva.com/nota/2026-2-22-5-0-25-el-hospital-municipal-consolida-su-plan-director-con-una-ampliacion-historica | H24: =IF(C24="", "", IFERROR(VLOOKUP(C24, 'Tabla 2'!$A$2:$D$298, 2, FALSE), "")) -> Local BB | I24: =IF(C24="", "", IFERROR(VLOOKUP(C24, 'Tabla 2'!$A$2:$D$298, 3, FALSE), "")) -> 1 | J24: =IF(C24="", "", IFERROR(VLOOKUP(C24, 'Tabla 2'!$A$2:$D$298, 4, FALSE), "")) -> 900000 | K24: Positivo | M24: Sustentabilidad | N24: Relaciones con la Comunidad | O24: No menciona | P24: 1
A25: 46075 | B25: El Hospital Municipal consolida su plan director con una ampliación histórica | C25: La Nueva Provincia | D25: Espontánea | E25: =IF(D25<>"","Orgánica","") -> Orgánica | F25: Reporte de noticias a través de la plataforma Sentinel Global News Group. | G25: https://sentinel.globalnewsgroup.com/ver-noticia?8Aa4j7y426naa627XRILnrA-vMW8m9BUZQ5iNg6PrzU | H25: Local BB | I25: 1 | J25: 900000 | K25: Positivo | M25: Sustentabilidad | N25: Relaciones con la Comunidad | O25: No menciona | P25: 1
A26: 46077 | B26: Unipar renueva cargos ejecutivos y refuerza su liderazgo institucional en la región | C26: Norte en Línea | D26: Proactiva | E26: =IF(D26<>"","Orgánica","") -> Orgánica | F26: Información sobre la renovación de cargos ejecutivos y el refuerzo del liderazgo institucional de Unipar en la región. | G26: https://norteenlinea.com/unipar-renueva-cargos-ejecutivos-y-refuerza-su-liderazgo-institucional-en-la-region/ | H26: =IF(C26="", "", IFERROR(VLOOKUP(C26, 'Tabla 2'!$A$2:$D$298, 2, FALSE), "")) -> Generalista Nacional | I26: =IF(C26="", "", IFERROR(VLOOKUP(C26, 'Tabla 2'!$A$2:$D$298, 3, FALSE), "")) -> 3 | J26: =IF(C26="", "", IFERROR(VLOOKUP(C26, 'Tabla 2'!$A$2:$D$298, 4, FALSE), "")) -> 0 | K26: Positivo | L26: TRUE | M26: Institucional | N26: Generalidades | O26: No menciona | P26: 1
A27: 46077 | B27: Sanar después de la tormenta: cómo nació el programa de salud mental de Unipar ante la catástrofe | C27: Sustenomics | D27: Proactiva | E27: =IF(D27<>"","Orgánica","") -> Orgánica | F27: Relato sobre el origen y desarrollo del programa de salud mental de Unipar frente a la catástrofe. | G27: https://sustenomics.com/sanar-despues-de-la-tormenta-como-nacio-el-programa-de-salud-mental-de-unipar-ante-la-catastrofe/ | H27: =IF(C27="", "", IFERROR(VLOOKUP(C27, 'Tabla 2'!$A$2:$D$298, 2, FALSE), "")) -> Sustentabilidad Nacional | I27: =IF(C27="", "", IFERROR(VLOOKUP(C27, 'Tabla 2'!$A$2:$D$298, 3, FALSE), "")) -> 1 | J27: =IF(C27="", "", IFERROR(VLOOKUP(C27, 'Tabla 2'!$A$2:$D$298, 4, FALSE), "")) -> 700000 | K27: Positivo | L27: TRUE | M27: Sustentabilidad | N27: Relaciones con la Comunidad | O27: Guillermo Petracci | P27: 1
A28: 46078 | B28: Unipar reordena su cúpula de recursos humanos y amplía su presencia sectorial regional | C28: Mercado | D28: Proactiva | E28: =IF(D28<>"","Orgánica","") -> Orgánica | F28: Detalles sobre la reorganización de la cúpula de recursos humanos de Unipar y su expansión a nivel regional. | G28: https://mercado.com.ar/talento-y-liderazgo/unipar-reordena-su-cupula-de-recursos-humanos-y-amplia-su-presencia-sectorial-regional/ | H28: =IF(C28="", "", IFERROR(VLOOKUP(C28, 'Tabla 2'!$A$2:$D$298, 2, FALSE), "")) -> Negocio Nacional | I28: =IF(C28="", "", IFERROR(VLOOKUP(C28, 'Tabla 2'!$A$2:$D$298, 3, FALSE), "")) -> 1 | J28: =IF(C28="", "", IFERROR(VLOOKUP(C28, 'Tabla 2'!$A$2:$D$298, 4, FALSE), "")) -> 500000 | K28: Positivo | L28: TRUE | M28: Institucional | N28: Marca Empleadora/RRHH | O28: No menciona | P28: 1
A29: 46079 | B29: Aún en crisis de consumo, las empresas cumplieron con el regalo por vuelta a clases | C29: iProfesional | D29: Proactiva | E29: =IF(D29<>"","Orgánica","") -> Orgánica | F29: Informe sobre cómo las empresas mantuvieron la entrega de regalos por la vuelta a clases a pesar de la crisis de consumo. | G29: https://www.iprofesional.com/management/448966-aun-en-crisis-de-consumo-las-empresas-cumplieron-con-el-regalo-por-vuelta-a-clases | H29: =IF(C29="", "", IFERROR(VLOOKUP(C29, 'Tabla 2'!$A$2:$D$298, 2, FALSE), "")) -> Generalista Nacional | I29: =IF(C29="", "", IFERROR(VLOOKUP(C29, 'Tabla 2'!$A$2:$D$298, 3, FALSE), "")) -> 1 | J29: =IF(C29="", "", IFERROR(VLOOKUP(C29, 'Tabla 2'!$A$2:$D$298, 4, FALSE), "")) -> 800000 | K29: Positivo | L29: TRUE | M29: Institucional | N29: Marca Empleadora/RRHH | O29: Laura Gutierrez | P29: 1
A30: 46082 | B30: El Departamento de |óvenes presentó su agenda de trabajo para este año | C30: La Nueva Provincia | D30: Espontánea | E30: Orgánica | F30: Reporte de noticias a través de la plataforma Sentinel Global News Group. | G30: https://sentinel.globalnewsgroup.com/ver-noticia?fHcvtx0QLhew5hvQz3FRLLPtVBVHDHuBPCa72-z7rp4 | H30: =IF(C30="", "", IFERROR(VLOOKUP(C30, 'Tabla 2'!$A$2:$D$298, 2, FALSE), "")) -> Local BB | I30: =IF(C30="", "", IFERROR(VLOOKUP(C30, 'Tabla 2'!$A$2:$D$298, 3, FALSE), "")) -> 1 | J30: =IF(C30="", "", IFERROR(VLOOKUP(C30, 'Tabla 2'!$A$2:$D$298, 4, FALSE), "")) -> 900000 | K30: Positivo | L30: FALSE | M30: Sustentabilidad | N30: Relaciones con la Comunidad | O30: No menciona | P30: 1
A31: 46082 | B31: Nombramientos corporativos | C31: BAE Negocios | D31: Proactiva | E31: Orgánica | F31: Reporte de noticias a través de la plataforma Sentinel Global News Group. | G31: https://sentinel.globalnewsgroup.com/ver-noticia?KLH4WTlWeg-BLtejvBg9wPCclUS9j6NQh11XkK-m7eE | H31: =IF(C31="", "", IFERROR(VLOOKUP(C31, 'Tabla 2'!$A$2:$D$298, 2, FALSE), "")) -> Negocio Nacional | I31: =IF(C31="", "", IFERROR(VLOOKUP(C31, 'Tabla 2'!$A$2:$D$298, 3, FALSE), "")) -> 1 | J31: =IF(C31="", "", IFERROR(VLOOKUP(C31, 'Tabla 2'!$A$2:$D$298, 4, FALSE), "")) -> 800000 | K31: Positivo | L31: TRUE | M31: Institucional | N31: Generalidades | O31: No menciona | P31: 1
A32: 46083 | B32: Unipar renueva su liderazgo ejecutivo y gana peso institucional en la región | C32: InfoNegocios | D32: Proactiva | E32: Orgánica | F32: Información sobre la renovación del liderazgo ejecutivo de Unipar y su peso institucional en la región. | G32: https://infonegocios.info/infogerentes/unipar-renueva-su-liderazgo-ejecutivo-y-gana-peso-institucional-en-la-region-hr-y-representacion-sectorial-2026-2027#:~:text=de%20marzo%20%7C%202026-,Unipar%20renueva%20su%20liderazgo%20ejecutivo%20y%20gana%20peso%20institucional%20en,c%C3%A1maras%20del%20sector%20qu%C3%ADmico%20sudamericano. | H32: =IF(C32="", "", IFERROR(VLOOKUP(C32, 'Tabla 2'!$A$2:$D$298, 2, FALSE), "")) -> Negocio Nacional | I32: =IF(C32="", "", IFERROR(VLOOKUP(C32, 'Tabla 2'!$A$2:$D$298, 3, FALSE), "")) -> 2 | J32: =IF(C32="", "", IFERROR(VLOOKUP(C32, 'Tabla 2'!$A$2:$D$298, 4, FALSE), "")) -> 0 | K32: Positivo | L32: TRUE | M32: Institucional | N32: Generalidades | O32: No menciona | P32: 1
A33: 46085 | B33: Unipar renueva cargos ejecutivos en la región | C33: EBizLatam | D33: Proactiva | E33: Orgánica | F33: Información sobre la renovación de cargos ejecutivos de Unipar en la región. | G33: https://ebizlatam.com/unipar-renueva-cargos-ejecutivos-en-la-region/ | H33: =IF(C33="", "", IFERROR(VLOOKUP(C33, 'Tabla 2'!$A$2:$D$298, 2, FALSE), "")) -> Generalista Nacional | I33: =IF(C33="", "", IFERROR(VLOOKUP(C33, 'Tabla 2'!$A$2:$D$298, 3, FALSE), "")) -> 3 | J33: =IF(C33="", "", IFERROR(VLOOKUP(C33, 'Tabla 2'!$A$2:$D$298, 4, FALSE), "")) -> 0 | K33: Positivo | L33: TRUE | M33: Institucional | N33: Generalidades | O33: No menciona | P33: 1
A34: 46091 | B34: Un tema que se consolidó en 2025 fue la integridad: la relevancia de tener datos clave | C34: Sustenomics | D34: Proactiva | E34: Orgánica | F34: Artículo sobre la consolidación de la integridad y la relevancia de tener datos clave. | G34: https://sustenomics.com/un-tema-que-se-consolido-en-2025-fue-la-integridad-la-relevancia-de-tener-datos-clave/ | H34: =IF(C34="", "", IFERROR(VLOOKUP(C34, 'Tabla 2'!$A$2:$D$298, 2, FALSE), "")) -> Sustentabilidad Nacional | I34: =IF(C34="", "", IFERROR(VLOOKUP(C34, 'Tabla 2'!$A$2:$D$298, 3, FALSE), "")) -> 1 | J34: =IF(C34="", "", IFERROR(VLOOKUP(C34, 'Tabla 2'!$A$2:$D$298, 4, FALSE), "")) -> 700000 | K34: Positivo | M34: Institucional | N34: Marca Empleadora/RRHH | O34: No menciona | P34: 1
A35: 46092 | B35: Río Negro verificó obra en salina El Gualicho | C35: Cipolletti Digital | D35: Espontánea | E35: Orgánica | F35: Reporte sobre la verificación de obras en la salina El Gualicho por parte de Río Negro. | G35: https://www.cipollettidigital.com.ar/noticias/2026/03/11/75287-rio-negro-verifico-obra-en-salina-el-gualicho | H35: =IF(C35="", "", IFERROR(VLOOKUP(C35, 'Tabla 2'!$A$2:$D$298, 2, FALSE), "")) -> Generalista Nacional | I35: =IF(C35="", "", IFERROR(VLOOKUP(C35, 'Tabla 2'!$A$2:$D$298, 3, FALSE), "")) -> 3 | J35: =IF(C35="", "", IFERROR(VLOOKUP(C35, 'Tabla 2'!$A$2:$D$298, 4, FALSE), "")) -> 0 | K35: Positivo | L35: FALSE | M35: Institucional | N35: Generalidades | O35: No menciona | P35: 1
A36: 46092 | B36: Río Negro verificó obra en salinas El Gualicho | C36: Gobierno de Rio Negro | D36: Espontánea | E36: Orgánica | F36: Reporte oficial sobre la verificación de obras en las salinas El Gualicho. | G36: https://rionegro.gov.ar/articulo/58233/rio-negro-verifico-obra-en-salinas-el-gualicho | H36: =IF(C36="", "", IFERROR(VLOOKUP(C36, 'Tabla 2'!$A$2:$D$298, 2, FALSE), "")) -> Generalista Nacional | I36: =IF(C36="", "", IFERROR(VLOOKUP(C36, 'Tabla 2'!$A$2:$D$298, 3, FALSE), "")) -> 3 | J36: =IF(C36="", "", IFERROR(VLOOKUP(C36, 'Tabla 2'!$A$2:$D$298, 4, FALSE), "")) -> 0 | K36: Positivo | L36: FALSE | M36: Institucional | N36: Generalidades | O36: No menciona | P36: 1
A37: 46092 | B37: Río Negro verificó obra en salina El Gualicho | C37: Informativo Hoy | D37: Espontánea | E37: Orgánica | F37: Reporte sobre la verificación de obras en la salina El Gualicho. | G37: https://informativohoy.com.ar/rio-negro-verifico-obra-en-salina-el-gualicho/ | H37: =IF(C37="", "", IFERROR(VLOOKUP(C37, 'Tabla 2'!$A$2:$D$298, 2, FALSE), "")) -> Generalista Nacional | I37: =IF(C37="", "", IFERROR(VLOOKUP(C37, 'Tabla 2'!$A$2:$D$298, 3, FALSE), "")) -> 3 | J37: =IF(C37="", "", IFERROR(VLOOKUP(C37, 'Tabla 2'!$A$2:$D$298, 4, FALSE), "")) -> 0 | K37: Positivo | L37: FALSE | M37: Institucional | N37: Generalidades | O37: No menciona | P37: 1
A38: 46092 | B38: Salinas del Gualicho: el gobierno inspeccionó obras y controló el impacto ambiental a las empresas | C38: La Mañana Cipolletti | D38: Espontánea | E38: Orgánica | F38: El Gobierno de Río Negro inspeccionó obras y controló el impacto ambiental de las empresas en las salinas. | G38: https://www.lmcipolletti.com/provincia/salinas-del-gualicho-el-gobierno-inspecciono-obras-y-controlo-el-impacto-ambiental-las-empresas-n1231293#:~:text=El%20Gobierno%20de%20R%C3%ADo%20Negro,salinas%20m%C3%A1s%20grandes%20de%20Sudam%C3%A9rica. | H38: =IF(C38="", "", IFERROR(VLOOKUP(C38, 'Tabla 2'!$A$2:$D$298, 2, FALSE), "")) -> Generalista Nacional | I38: =IF(C38="", "", IFERROR(VLOOKUP(C38, 'Tabla 2'!$A$2:$D$298, 3, FALSE), "")) -> 3 | J38: =IF(C38="", "", IFERROR(VLOOKUP(C38, 'Tabla 2'!$A$2:$D$298, 4, FALSE), "")) -> 0 | K38: Positivo | L38: No | M38: Sustentabilidad | N38: Estrategia ESG | O38: No menciona | P38: 1
A39: 46094 | B39: Cuáles son las 70 mejores empresas para trabajar en Argentina en 2026 | C39: Infobae | D39: Proactiva | E39: Orgánica | F39: Artículo sobre las 70 mejores empresas para trabajar en Argentina en 2026. | G39: https://www.infobae.com/tendencias/2026/03/13/cuales-son-las-70-mejores-empresas-para-trabajar-en-argentina-en-2026/ | H39: =IF(C39="", "", IFERROR(VLOOKUP(C39, 'Tabla 2'!$A$2:$D$298, 2, FALSE), "")) -> Generalista Nacional | I39: =IF(C39="", "", IFERROR(VLOOKUP(C39, 'Tabla 2'!$A$2:$D$298, 3, FALSE), "")) -> 1 | J39: =IF(C39="", "", IFERROR(VLOOKUP(C39, 'Tabla 2'!$A$2:$D$298, 4, FALSE), "")) -> 6000000 | K39: Positivo | L39: TRUE | M39: Institucional | N39: Marca Empleadora/RRHH | O39: No menciona | P39: 1
A40: 46094 | B40: Unipar quedó entre los mejores lugares para trabajar en Argentina y se ubicó 21 en el ranking 2026 | C40: Argen Ports web | D40: Proactiva | E40: Orgánica | F40: Unipar fue reconocida en el ranking de los mejores lugares para trabajar en Argentina. | G40: https://argenports.com/nota/unipar-quedo-entre-los-mejores-lugares-para-trabajar-en-argentina-y-se-ubico-21-en-el-ranking-2026/#:~:text=Unipar%20fue%20reconocida%20en%20el,100.000%20personasen%20todo%20el%20pa%C3%ADs. | H40: =IF(C40="", "", IFERROR(VLOOKUP(C40, 'Tabla 2'!$A$2:$D$298, 2, FALSE), "")) -> Local BB | I40: =IF(C40="", "", IFERROR(VLOOKUP(C40, 'Tabla 2'!$A$2:$D$298, 3, FALSE), "")) -> 2 | J40: =IF(C40="", "", IFERROR(VLOOKUP(C40, 'Tabla 2'!$A$2:$D$298, 4, FALSE), "")) -> 0 | K40: Positivo | L40: TRUE | M40: Institucional | N40: Marca Empleadora/RRHH | O40: No menciona | P40: 1
...

Sheet Tabla 2
A1: LISTA DE MEDIOS (Base) | B1: Tipo de Medio (Base) | C1: Tier (Base) | D1: Valor Estimado (Base) | E1: Voceros (Base)
A2: Clarin | B2: Generalista Nacional | C2: 1 | D2: 6000000 | E2: Rodrigo Cannaval
A3: La Nación | B3: Generalista Nacional | C3: 1 | D3: 7000000 | E3: Guillermo Petracci
A4: El Cronista | B4: Negocio Nacional | C4: 1 | D4: 1200000 | E4: Laura Gutiérrez
A5: Ámbito Financiero | B5: Negocio Nacional | C5: 1 | D5: 1200000 | E5: Martín Fasano
A6: Apertura | B6: Negocio Nacional | C6: 1 | D6: 1200000 | E6: Alexandre Castro
A7: BAE Negocios | B7: Negocio Nacional | C7: 1 | D7: 800000 | E7: Matías Moreno
A8: Infobae | B8: Generalista Nacional | C8: 1 | D8: 6000000 | E8: Gabriel Stachiotti
A9: iProfesional | B9: Generalista Nacional | C9: 1 | D9: 800000 | E9: Cecilia Marinesco
A10: Mercado | B10: Negocio Nacional | C10: 1 | D10: 500000 | E10: Ignacio Garriz
A11: Revista Petroquímica | B11: Negocio Nacional | C11: 1 | D11: 500000 | E11: Rodrigo Capdevila
A12: TV Pública | B12: Generalista Nacional | C12: 1 | D12: 1800 | E12: Ezequiel Báez
A13: El Tribuno | B13: Generalista Nacional | C13: 1 | D13: 800000
A14: EconoJournal | B14: Negocio Nacional | C14: 1 | D14: 1800000
A15: El Economista | B15: Negocio Nacional | C15: 1 | D15: 800000
A16: La Opinión Austral | B16: Generalista Nacional | C16: 1 | D16: 800000
A17: Visión Sustentable | B17: Sustentabilidad Nacional | C17: 1 | D17: 600000
A18: Sustenomics | B18: Sustentabilidad Nacional | C18: 1 | D18: 700000
A19: Prensa Económica | B19: Generalista Nacional | C19: 1 | D19: 200000
A20: Forbes | B20: Negocio Nacional | C20: 1 | D20: 8000000
A21: Perfil | B21: Generalista Nacional | C21: 1 | D21: 1000000
A22: Diario Río Negro | B22: Generalista Nacional | C22: 1 | D22: 500000
A23: El Observador | B23: Negocios | C23: 1 | D23: 500000
A24: Canal 7 Bahia Blanca | B24: Local BB | C24: 1 | D24: 5000000
... A307: Semanario Bariloche | B307: Generalista Nacional | C307: 3 | D307: 0
A308: Inversor Latam | B308: Generalista Nacional | C308: 3 | D308: ARS0,00
A309: Bahía Política | B309: Local BB | C309: 3 | D309: ARS0,00
A310: Crónica del NOA | B310: Generalista Nacional | C310: 3 | D310: ARS0,00
A311: Revista Imagen | B311: Generalista Nacional | C311: 3 | D311: ARS0,00
A312: Nuevo Enfoque Urbano | B312: Generalista Nacional | C312: 3 | D312: 0
A313: BNAmericas | B313: Generalista Nacional | C313: 1 | D313: 1000000

Sheet Resumen Tier 1
A1: Mes | B1: Tier1
A2: 2026-ene | B2: 5
A3: 2026-feb | B3: 11
A4: 2026-mar | B4: 9
A5: 2026-abr | B5: 13
A6: 2026-may | B6: 5
A7: 2026-jun | B7: 18
A8: 46204 | B8: 7
A9: Total | B9: =SUM(B2:B8) -> 68
